<?xml version="1.0" ?>
<sdf version="1.9" xmlns:xacro="http://ros.org/wiki/xacro">
  <xacro:arg name="namespace" default="uav_0"/>
  <model name="$(arg namespace)">
    <include merge="true">
      <uri>https://fuel.gazebosim.org/1.0/PX4/models/x500</uri>
    </include>

    <!-- Velocity Control with Namespaced Topic -->
    <plugin
      filename="gz-sim-velocity-control-system"
      name="gz::sim::systems::VelocityControl">
      <link_name>base_link</link_name>
      <topic>/model/$(arg namespace)/cmd_vel</topic>
    </plugin>
    
    <plugin
      filename="gz-sim-odometry-publisher-system"
      name="gz::sim::systems::OdometryPublisher">
      <odom_frame>world</odom_frame>
      <robot_base_frame>base_link</robot_base_frame>
      <dimensions>3</dimensions>
    </plugin>

    <!-- Broadcast TF for all links -->
    <plugin
      filename="gz-sim-pose-publisher-system"
      name="gz::sim::systems::PosePublisher">
      <publish_link_pose>true</publish_link_pose>
      <publish_sensor_pose>true</publish_sensor_pose>
      <publish_collision_pose>false</publish_collision_pose>
      <publish_visual_pose>false</publish_visual_pose>
      <publish_nested_model_pose>true</publish_nested_model_pose>
      <use_pose_vector_msg>true</use_pose_vector_msg>
      <static_publisher>true</static_publisher>
      <static_update_frequency>1</static_update_frequency>
    </plugin>

    <!-- Camera (Fixed on base) -->
    <link name="camera_link">
      <pose relative_to="base_link">0.1 0 0.1 0 0 0</pose>
      <visual name="visual">
        <geometry><box><size>0.02 0.05 0.02</size></box></geometry>
        <material><ambient>1 0 0 1</ambient><diffuse>1 0 0 1</diffuse></material>
      </visual>
      <collision name="collision">
        <geometry><box><size>0.02 0.05 0.02</size></box></geometry>
      </collision>
      <sensor name="camera" type="camera">
        <camera>
          <horizontal_fov>1.047</horizontal_fov>
          <image>
            <width>640</width>
            <height>480</height>
          </image>
          <clip>
            <near>0.1</near>
            <far>100</far>
          </clip>
        </camera>
        <always_on>1</always_on>
        <update_rate>30</update_rate>
        <visualize>true</visualize>
        <topic>/model/$(arg namespace)/camera/image_raw</topic>
      </sensor>
    </link>
    <joint name="camera_joint" type="fixed">
        <parent>base_link</parent>
        <child>camera_link</child>
    </joint>

    <!-- Downward Camera -->
    <link name="down_camera_link">
      <pose relative_to="base_link">0 0 -0.05 0 1.5708 0</pose>
      <visual name="visual">
        <geometry><box><size>0.02 0.05 0.02</size></box></geometry>
        <material><ambient>1 1 0 1</ambient><diffuse>1 1 0 1</diffuse></material>
      </visual>
      <collision name="collision">
        <geometry><box><size>0.02 0.05 0.02</size></box></geometry>
      </collision>
      <sensor name="down_camera" type="camera">
        <camera>
          <horizontal_fov>1.047</horizontal_fov>
          <image>
            <width>640</width>
            <height>480</height>
          </image>
          <clip>
            <near>0.1</near>
            <far>100</far>
          </clip>
        </camera>
        <always_on>1</always_on>
        <update_rate>30</update_rate>
        <visualize>true</visualize>
        <topic>/model/$(arg namespace)/down_camera/image_raw</topic>
      </sensor>
    </link>
    <joint name="down_camera_joint" type="fixed">
        <parent>base_link</parent>
        <child>down_camera_link</child>
    </joint>

    <!-- IMU Sensor -->
    <link name="imu_link">
        <pose relative_to="base_link">0 0 0 0 0 0</pose>
        <inertial>
            <mass>0.01</mass>
            <inertia>
                <ixx>0.00001</ixx> <ixy>0</ixy> <ixz>0</ixz>
                <iyy>0.00001</iyy> <iyz>0</iyz>
                <izz>0.00001</izz>
            </inertia>
        </inertial>
        <sensor name="imu_sensor" type="imu">
            <always_on>1</always_on>
            <update_rate>100</update_rate>
            <visualize>true</visualize>
            <topic>/model/$(arg namespace)/imu</topic>
        </sensor>
    </link>
    <joint name="imu_joint" type="fixed">
        <parent>base_link</parent>
        <child>imu_link</child>
    </joint>

    <!-- 3D Lidar Top Link -->
    <link name="lidar_link">
        <pose relative_to="base_link">0 0 0.25 0 0 0</pose> <!-- On top of X500 -->
        <visual name="visual">
            <geometry>
                <cylinder>
                    <radius>0.04</radius>
                    <length>0.05</length>
                </cylinder>
            </geometry>
            <material><ambient>0 0 1 1</ambient><diffuse>0 0 1 1</diffuse></material>
        </visual>
        <!-- Lidar Mount (Visual Stand) -->
        <visual name="mount_visual">
            <pose>0 0 -0.05 0 0 0</pose> <!-- Below the lidar -->
            <geometry>
                <cylinder>
                    <radius>0.02</radius>
                    <length>0.06</length>
                </cylinder>
            </geometry>
            <material><ambient>0.2 0.2 0.2 1</ambient><diffuse>0.2 0.2 0.2 1</diffuse></material>
        </visual>
        <collision name="mount_collision">
            <pose>0 0 -0.05 0 0 0</pose>
            <geometry>
                <cylinder>
                    <radius>0.02</radius>
                    <length>0.06</length>
                </cylinder>
            </geometry>
        </collision>
        
        <!-- 3D LiDAR -->
        <sensor name="lidar_3d" type="gpu_lidar">
          <topic>/model/$(arg namespace)/lidar/points</topic>
          <update_rate>10</update_rate>
          <ray>
            <scan>
              <horizontal>
                <samples>360</samples>
                <resolution>1</resolution>
                <min_angle>-3.14159</min_angle>
                <max_angle>3.14159</max_angle>
              </horizontal>
              <vertical>
                <samples>16</samples>
                <resolution>1</resolution>
                <min_angle>-0.261799</min_angle>
                <max_angle>0.261799</max_angle>
              </vertical>
            </scan>
            <range>
              <min>0.1</min>
              <max>30.0</max>
            </range>
          </ray>
          <visualize>false</visualize>
          <always_on>1</always_on>
        </sensor>
    </link>

    <joint name="lidar_joint" type="revolute">
        <parent>base_link</parent>
        <child>lidar_link</child>
        <axis>
            <xyz>0 0 1</xyz>
            <limit>
                <lower>-10000000000000000</lower>
                <upper>10000000000000000</upper>
            </limit>
        </axis>
    </joint>

    <!-- Sonar (Simulated as Downward Lidar) -->
    <link name="sonar_link">
        <pose relative_to="base_link">0 0 -0.05 0 1.5708 0</pose> <!-- Bottom, pointing down (pitch 90) -->
        <visual name="visual">
            <geometry>
                <box><size>0.02 0.02 0.01</size></box>
            </geometry>
            <material><ambient>0 1 0 1</ambient><diffuse>0 1 0 1</diffuse></material>
        </visual>
        <collision name="sonar_collision">
            <geometry>
                <box><size>0.02 0.02 0.01</size></box>
            </geometry>
        </collision>
        
        <sensor name="sonar" type="gpu_lidar">
            <topic>/model/$(arg namespace)/sonar/range</topic>
            <update_rate>50</update_rate>
            <visualize>true</visualize>
            <ray>
                <scan>
                    <horizontal>
                        <samples>10</samples>
                        <resolution>1</resolution>
                        <min_angle>-0.14835</min_angle>
                        <max_angle>0.14835</max_angle>
                    </horizontal>
                    <vertical>
                        <samples>10</samples>
                        <resolution>1</resolution>
                        <min_angle>-0.14835</min_angle>
                        <max_angle>0.14835</max_angle>
                    </vertical>
                </scan>
                <range>
                    <min>0.02</min>
                    <max>4.0</max>
                    <resolution>0.01</resolution>
                </range>
            </ray>
        </sensor>
    </link>

    <joint name="sonar_joint" type="fixed">
        <parent>base_link</parent>
        <child>sonar_link</child>
    </joint>


    <!-- Joint Controller for Spinning Lidar -->
    <plugin
      filename="gz-sim-joint-controller-system"
      name="gz::sim::systems::JointController">
      <joint_name>lidar_joint</joint_name>
      <initial_velocity>10.0</initial_velocity>
    </plugin>

  </model>
</sdf>
